Workbook
Name NativeTimeline_Date: #N/A
Name Slicer_Region: #N/A

Sheet Project Instructions
A1: PR. Final Project - "Data Intelligence Dashboard"
A2: Dataset: Use the 'Final Project Dataset' sheet containing 200+ records of customer transactions. Objective: Create a full-fledged analysis and reporting solution using Excel to analyze customer transactions, find insights, and build visualizations and dashboards. Key Topics to Implement: - Date & Time Functions: TODAY, NOW, DATEDIF, EOMONTH - FILTER Function for multi-value returns - Conditional Formatting with Icons/Arrows - Create Timestamp (using NOW and iterative calculations) - WHAT-IF Analysis: Scenario Manager, Goal Seek - Linear Regression using Data Analysis Toolpak - Data Analysis & Storytelling from the dataset - Use GroupBy concepts to find High-Value Customers using formulas - Create Dashboard using: - Pivot Tables - Pivot Charts (Bar, Line, Pie) - Slicers and Timelines - KPI Indicators with Conditional Formatting - Find most frequently purchased product or repeating names using formulas - Compare two lists and extract matching names in a new column - Create Abbreviations using TEXT functions - Build a final report with insights and storytelling Deliverable: - Well-structured workbook with multiple sheets (Raw Data, Analysis, Visualizations, Dashboard) - Summary Insights with key metrics: Total Revenue, Top Customers, Most Sold Products, Regional Sales - Use of all required formulas and functions as listed above

Sheet Final Project Dataset
A1: Transaction_ID | B1: Date | C1: Customer_ID | D1: Customer_Name | E1: Product_ID | F1: Product_Name | G1: Category | H1: Quantity | I1: Unit_Price | J1: Payment_Method | K1: Region | L1: Customer_Segment | M1: Customer_Since | N1: Total_Amount | O1: Total_Customer_Spending | P1: Customer_Type | Q1: Product_Frequency | R1: Customer_Code | V1: DATE & TIME FUNCTION | X1: Total Quantity | Y1: Total Unit_price | Z1: Total Amount
A2: TRX0155 | B2: 45393 | C2: CUST01 | D2: Paul Baker | E2: P009 | F2: Monitor | G2: Electronics | H2: 3 | I2: 249.99 | J2: Cash | K2: Central | L2: Basic | M2: 44425 | N2: 749.97 | O2: =SUMIFS($N:$N,$D:$D,D2) -> 8309.74 | P2: =IF(O2>10000,"High Value","Normal") -> Normal | Q2: =COUNTIF($F:$F,F2) -> 26 | R2: =UPPER(LEFT(D2,1)&MID(D2,FIND(" ",D2)+1,1)) -> PB | V2: Today | W2: =TODAY() -> 46071 | X2: =SUM(H2:H251) -> 753 | Y2: =SUM(I2:I251) -> 74167.5 | Z2: =SUM(N2:N251) -> 229192.47
A3: TRX0023 | B3: 45396 | C3: CUST02 | D3: Joseph Jackson | E3: P009 | F3: Monitor | G3: Electronics | H3: 3 | I3: 249.99 | J3: Credit Card | K3: Central | L3: Premium | M3: 44575 | N3: 749.97 | O3: =SUMIFS($N:$N,$D:$D,D3) -> 6949.84 | P3: =IF(O3>10000,"High Value","Normal") -> Normal | Q3: =COUNTIF($F:$F,F3) -> 26 | R3: =UPPER(LEFT(D3,1)&MID(D3,FIND(" ",D3)+1,1)) -> JJ | V3: Now | W3: =NOW() -> 46071.9
A4: TRX0139 | B4: 45399 | C4: CUST03 | D4: Kevin Scott | E4: P005 | F4: Blender | G4: Appliances | H4: 3 | I4: 59.99 | J4: PayPal | K4: South | L4: Standard | M4: 45262 | N4: 179.97 | O4: =SUMIFS($N:$N,$D:$D,D4) -> 3259.87 | P4: =IF(O4>10000,"High Value","Normal") -> Normal | Q4: =COUNTIF($F:$F,F4) -> 29 | R4: =UPPER(LEFT(D4,1)&MID(D4,FIND(" ",D4)+1,1)) -> KS | V4: Eomonth | W4: =EOMONTH(W2,0) -> 46081
A5: TRX0043 | B5: 45400 | C5: CUST04 | D5: Kathleen Bennett | E5: P005 | F5: Blender | G5: Appliances | H5: 3 | I5: 59.99 | J5: Cash | K5: North | L5: Premium | M5: 45114 | N5: 179.97 | O5: =SUMIFS($N:$N,$D:$D,D5) -> 4309.81 | P5: =IF(O5>10000,"High Value","Normal") -> Normal | Q5: =COUNTIF($F:$F,F5) -> 29 | R5: =UPPER(LEFT(D5,1)&MID(D5,FIND(" ",D5)+1,1)) -> KB
A6: TRX0212 | B6: 45400 | C6: CUST05 | D6: Michael Brown | E6: P008 | F6: Bookshelf | G6: Furniture | H6: 5 | I6: 149.99 | J6: Credit Card | K6: North | L6: Premium | M6: 45295 | N6: 749.95 | O6: =SUMIFS($N:$N,$D:$D,D6) -> 6169.74 | P6: =IF(O6>10000,"High Value","Normal") -> Normal | Q6: =COUNTIF($F:$F,F6) -> 35 | R6: =UPPER(LEFT(D6,1)&MID(D6,FIND(" ",D6)+1,1)) -> MB
A7: TRX0092 | B7: 45403 | C7: CUST06 | D7: Dorothy Nelson | E7: P005 | F7: Blender | G7: Appliances | H7: 2 | I7: 59.99 | J7: Cash | K7: West | L7: Standard | M7: 44746 | N7: 119.98 | O7: =SUMIFS($N:$N,$D:$D,D7) -> 8269.79 | P7: =IF(O7>10000,"High Value","Normal") -> Normal | Q7: =COUNTIF($F:$F,F7) -> 29 | R7: =UPPER(LEFT(D7,1)&MID(D7,FIND(" ",D7)+1,1)) -> DN | V7: Time Stamp | W7: 0.74930556
A8: TRX0193 | B8: 45403 | C8: CUST07 | D8: Dorothy Nelson | E8: P003 | F8: Headphones | G8: Electronics | H8: 5 | I8: 149.99 | J8: Credit Card | K8: Central | L8: Standard | M8: 44418 | N8: 749.95 | O8: =SUMIFS($N:$N,$D:$D,D8) -> 8269.79 | P8: =IF(O8>10000,"High Value","Normal") -> Normal | Q8: =COUNTIF($F:$F,F8) -> 16 | R8: =UPPER(LEFT(D8,1)&MID(D8,FIND(" ",D8)+1,1)) -> DN
A9: TRX0240 | B9: 45403 | C9: CUST08 | D9: Charles Allen | E9: P005 | F9: Blender | G9: Appliances | H9: 3 | I9: 59.99 | J9: Debit Card | K9: South | L9: Basic | M9: 45007 | N9: 179.97 | O9: =SUMIFS($N:$N,$D:$D,D9) -> 5089.73 | P9: =IF(O9>10000,"High Value","Normal") -> Normal | Q9: =COUNTIF($F:$F,F9) -> 29 | R9: =UPPER(LEFT(D9,1)&MID(D9,FIND(" ",D9)+1,1)) -> CA
A10: TRX0135 | B10: 45405 | C10: CUST09 | D10: Robert Thomas | E10: P001 | F10: Laptop | G10: Electronics | H10: 3 | I10: 899.99 | J10: PayPal | K10: East | L10: Standard | M10: 45299 | N10: 2699.97 | O10: =SUMIFS($N:$N,$D:$D,D10) -> 3509.9 | P10: =IF(O10>10000,"High Value","Normal") -> Normal | Q10: =COUNTIF($F:$F,F10) -> 24 | R10: =UPPER(LEFT(D10,1)&MID(D10,FIND(" ",D10)+1,1)) -> RT
A11: TRX0185 | B11: 45408 | C11: CUST10 | D11: Karen Hill | E11: P005 | F11: Blender | G11: Appliances | H11: 3 | I11: 59.99 | J11: Cash | K11: West | L11: Premium | M11: 45207 | N11: 179.97 | O11: =SUMIFS($N:$N,$D:$D,D11) -> 8009.77 | P11: =IF(O11>10000,"High Value","Normal") -> Normal | Q11: =COUNTIF($F:$F,F11) -> 29 | R11: =UPPER(LEFT(D11,1)&MID(D11,FIND(" ",D11)+1,1)) -> KH
A12: TRX0138 | B12: 45408 | C12: CUST11 | D12: Susan Green | E12: P008 | F12: Bookshelf | G12: Furniture | H12: 1 | I12: 149.99 | J12: Credit Card | K12: West | L12: Standard | M12: 45103 | N12: 149.99 | O12: =SUMIFS($N:$N,$D:$D,D12) -> 1979.89 | P12: =IF(O12>10000,"High Value","Normal") -> Normal | Q12: =COUNTIF($F:$F,F12) -> 35 | R12: =UPPER(LEFT(D12,1)&MID(D12,FIND(" ",D12)+1,1)) -> SG | V12: WHAT IF ( Scenario Manager )
A13: TRX0209 | B13: 45408 | C13: CUST12 | D13: Kathleen Bennett | E13: P008 | F13: Bookshelf | G13: Furniture | H13: 5 | I13: 149.99 | J13: Debit Card | K13: North | L13: Basic | M13: 44830 | N13: 749.95 | O13: =SUMIFS($N:$N,$D:$D,D13) -> 4309.81 | P13: =IF(O13>10000,"High Value","Normal") -> Normal | Q13: =COUNTIF($F:$F,F13) -> 35 | R13: =UPPER(LEFT(D13,1)&MID(D13,FIND(" ",D13)+1,1)) -> KB | V13: Qty | W13: 200
A14: TRX0246 | B14: 45408 | C14: CUST13 | D14: Peter Richardson | E14: P008 | F14: Bookshelf | G14: Furniture | H14: 3 | I14: 149.99 | J14: Cash | K14: North | L14: Premium | M14: 44806 | N14: 449.97 | O14: =SUMIFS($N:$N,$D:$D,D14) -> 5949.85 | P14: =IF(O14>10000,"High Value","Normal") -> Normal | Q14: =COUNTIF($F:$F,F14) -> 35 | R14: =UPPER(LEFT(D14,1)&MID(D14,FIND(" ",D14)+1,1)) -> PR | V14: Unit Price | W14: 250
A15: TRX0067 | B15: 45409 | C15: CUST14 | D15: Dennis Gray | E15: P005 | F15: Blender | G15: Appliances | H15: 3 | I15: 59.99 | J15: Credit Card | K15: North | L15: Standard | M15: 45351 | N15: 179.97 | O15: =SUMIFS($N:$N,$D:$D,D15) -> 479.92 | P15: =IF(O15>10000,"High Value","Normal") -> Normal | Q15: =COUNTIF($F:$F,F15) -> 29 | R15: =UPPER(LEFT(D15,1)&MID(D15,FIND(" ",D15)+1,1)) -> DG | V15: Total Amount | W15: =W14*W13 -> 50000
A16: TRX0191 | B16: 45409 | C16: CUST15 | D16: Michelle Rogers | E16: P002 | F16: Smartphone | G16: Electronics | H16: 3 | I16: 699.99 | J16: Credit Card | K16: West | L16: Basic | M16: 44577 | N16: 2099.97 | O16: =SUMIFS($N:$N,$D:$D,D16) -> 4199.94 | P16: =IF(O16>10000,"High Value","Normal") -> Normal | Q16: =COUNTIF($F:$F,F16) -> 31 | R16: =UPPER(LEFT(D16,1)&MID(D16,FIND(" ",D16)+1,1)) -> MR
A17: TRX0230 | B17: 45409 | C17: CUST16 | D17: George Adams | E17: P001 | F17: Laptop | G17: Electronics | H17: 1 | I17: 899.99 | J17: Debit Card | K17: North | L17: Standard | M17: 44920 | N17: 899.99 | O17: =SUMIFS($N:$N,$D:$D,D17) -> 3779.93 | P17: =IF(O17>10000,"High Value","Normal") -> Normal | Q17: =COUNTIF($F:$F,F17) -> 24 | R17: =UPPER(LEFT(D17,1)&MID(D17,FIND(" ",D17)+1,1)) -> GA
A18: TRX0049 | B18: 45410 | C18: CUST17 | D18: Mark Carter | E18: P008 | F18: Bookshelf | G18: Furniture | H18: 4 | I18: 149.99 | J18: Debit Card | K18: North | L18: Premium | M18: 45374 | N18: 599.96 | O18: =SUMIFS($N:$N,$D:$D,D18) -> 15659.65 | P18: =IF(O18>10000,"High Value","Normal") -> High Value | Q18: =COUNTIF($F:$F,F18) -> 35 | R18: =UPPER(LEFT(D18,1)&MID(D18,FIND(" ",D18)+1,1)) -> MC
A19: TRX0134 | B19: 45410 | C19: CUST18 | D19: Maria Garcia | E19: P002 | F19: Smartphone | G19: Electronics | H19: 2 | I19: 699.99 | J19: Cash | K19: North | L19: Basic | M19: 44781 | N19: 1399.98 | O19: =SUMIFS($N:$N,$D:$D,D19) -> 1909.93 | P19: =IF(O19>10000,"High Value","Normal") -> Normal | Q19: =COUNTIF($F:$F,F19) -> 31 | R19: =UPPER(LEFT(D19,1)&MID(D19,FIND(" ",D19)+1,1)) -> MG | V19: WHAT IF ( Goal Seek )
A20: TRX0122 | B20: 45410 | C20: CUST19 | D20: Mark Carter | E20: P001 | F20: Laptop | G20: Electronics | H20: 4 | I20: 899.99 | J20: Credit Card | K20: West | L20: Standard | M20: 45327 | N20: 3599.96 | O20: =SUMIFS($N:$N,$D:$D,D20) -> 15659.65 | P20: =IF(O20>10000,"High Value","Normal") -> High Value | Q20: =COUNTIF($F:$F,F20) -> 24 | R20: =UPPER(LEFT(D20,1)&MID(D20,FIND(" ",D20)+1,1)) -> MC | V20: Qty | W20: 240
A21: TRX0222 | B21: 45410 | C21: CUST20 | D21: Virginia Sanders | E21: P009 | F21: Monitor | G21: Electronics | H21: 3 | I21: 249.99 | J21: Credit Card | K21: North | L21: Premium | M21: 45224 | N21: 749.97 | O21: =SUMIFS($N:$N,$D:$D,D21) -> 4789.79 | P21: =IF(O21>10000,"High Value","Normal") -> Normal | Q21: =COUNTIF($F:$F,F21) -> 26 | R21: =UPPER(LEFT(D21,1)&MID(D21,FIND(" ",D21)+1,1)) -> VS | V21: Unit Price | W21: 250
A22: TRX0231 | B22: 45412 | C22: CUST21 | D22: Barbara Young | E22: P002 | F22: Smartphone | G22: Electronics | H22: 5 | I22: 699.99 | J22: Cash | K22: West | L22: Basic | M22: 45167 | N22: 3499.95 | O22: =SUMIFS($N:$N,$D:$D,D22) -> 10649.8 | P22: =IF(O22>10000,"High Value","Normal") -> High Value | Q22: =COUNTIF($F:$F,F22) -> 31 | R22: =UPPER(LEFT(D22,1)&MID(D22,FIND(" ",D22)+1,1)) -> BY | V22: Total Amount | W22: =W21*W20 -> 60000
A23: TRX0239 | B23: 45413 | C23: CUST22 | D23: Patricia Moore | E23: P002 | F23: Smartphone | G23: Electronics | H23: 4 | I23: 699.99 | J23: Cash | K23: East | L23: Standard | M23: 44409 | N23: 2799.96 | O23: =SUMIFS($N:$N,$D:$D,D23) -> 9799.73 | P23: =IF(O23>10000,"High Value","Normal") -> Normal | Q23: =COUNTIF($F:$F,F23) -> 31 | R23: =UPPER(LEFT(D23,1)&MID(D23,FIND(" ",D23)+1,1)) -> PM
A24: TRX0204 | B24: 45415 | C24: CUST23 | D24: Cynthia Price | E24: P009 | F24: Monitor | G24: Electronics | H24: 4 | I24: 249.99 | J24: PayPal | K24: North | L24: Standard | M24: 44468 | N24: 999.96 | O24: =SUMIFS($N:$N,$D:$D,D24) -> 3769.83 | P24: =IF(O24>10000,"High Value","Normal") -> Normal | Q24: =COUNTIF($F:$F,F24) -> 26 | R24: =UPPER(LEFT(D24,1)&MID(D24,FIND(" ",D24)+1,1)) -> CP
A25: TRX0242 | B25: 45416 | C25: CUST24 | D25: Mark Carter | E25: P007 | F25: Desk | G25: Furniture | H25: 4 | I25: 299.99 | J25: Cash | K25: West | L25: Premium | M25: 44716 | N25: 1199.96 | O25: =SUMIFS($N:$N,$D:$D,D25) -> 15659.65 | P25: =IF(O25>10000,"High Value","Normal") -> High Value | Q25: =COUNTIF($F:$F,F25) -> 26 | R25: =UPPER(LEFT(D25,1)&MID(D25,FIND(" ",D25)+1,1)) -> MC | V25: Most Frequently Purchased Product
A26: TRX0071 | B26: 45422 | C26: CUST25 | D26: Nancy Collins | E26: P009 | F26: Monitor | G26: Electronics | H26: 5 | I26: 249.99 | J26: Credit Card | K26: West | L26: Standard | M26: 44525 | N26: 1249.95 | O26: =SUMIFS($N:$N,$D:$D,D26) -> 4189.77 | P26: =IF(O26>10000,"High Value","Normal") -> Normal | Q26: =COUNTIF($F:$F,F26) -> 26 | R26: =UPPER(LEFT(D26,1)&MID(D26,FIND(" ",D26)+1,1)) -> NC | V26: =INDEX(F:F,MATCH(MAX(Q:Q),Q:Q,0)) -> Bookshelf
A27: TRX0040 | B27: 45424 | C27: CUST26 | D27: Susan Green | E27: P007 | F27: Desk | G27: Furniture | H27: 5 | I27: 299.99 | J27: PayPal | K27: East | L27: Basic | M27: 45168 | N27: 1499.95 | O27: =SUMIFS($N:$N,$D:$D,D27) -> 1979.89 | P27: =IF(O27>10000,"High Value","Normal") -> Normal | Q27: =COUNTIF($F:$F,F27) -> 26 | R27: =UPPER(LEFT(D27,1)&MID(D27,FIND(" ",D27)+1,1)) -> SG
A28: TRX0235 | B28: 45424 | C28: CUST27 | D28: Linda Martin | E28: P004 | F28: Coffee Maker | G28: Appliances | H28: 3 | I28: 79.99 | J28: PayPal | K28: East | L28: Premium | M28: 45012 | N28: 239.97 | O28: =SUMIFS($N:$N,$D:$D,D28) -> 1289.9 | P28: =IF(O28>10000,"High Value","Normal") -> Normal | Q28: =COUNTIF($F:$F,F28) -> 14 | R28: =UPPER(LEFT(D28,1)&MID(D28,FIND(" ",D28)+1,1)) -> LM
A29: TRX0004 | B29: 45424 | C29: CUST28 | D29: Patricia Moore | E29: P010 | F29: Keyboard | G29: Electronics | H29: 5 | I29: 89.99 | J29: Cash | K29: North | L29: Premium | M29: 44919 | N29: 449.95 | O29: =SUMIFS($N:$N,$D:$D,D29) -> 9799.73 | P29: =IF(O29>10000,"High Value","Normal") -> Normal | Q29: =COUNTIF($F:$F,F29) -> 34 | R29: =UPPER(LEFT(D29,1)&MID(D29,FIND(" ",D29)+1,1)) -> PM | V29: Unit 1 | W29: Unit 2 | X29: Final
A30: TRX0063 | B30: 45425 | C30: CUST29 | D30: Helen Roberts | E30: P005 | F30: Blender | G30: Appliances | H30: 2 | I30: 59.99 | J30: Debit Card | K30: Central | L30: Standard | M30: 45214 | N30: 119.98 | O30: =SUMIFS($N:$N,$D:$D,D30) -> 6459.79 | P30: =IF(O30>10000,"High Value","Normal") -> Normal | Q30: =COUNTIF($F:$F,F30) -> 29 | R30: =UPPER(LEFT(D30,1)&MID(D30,FIND(" ",D30)+1,1)) -> HR | V30: Meet | W30: Meet | X30: =IF(COUNTIF($V$30:$V$38,W30),W30,"-") -> Meet
A31: TRX0241 | B31: 45427 | C31: CUST30 | D31: Edward Mitchell | E31: P005 | F31: Blender | G31: Appliances | H31: 4 | I31: 59.99 | J31: Debit Card | K31: East | L31: Standard | M31: 44867 | N31: 239.96 | O31: =SUMIFS($N:$N,$D:$D,D31) -> 11919.77 | P31: =IF(O31>10000,"High Value","Normal") -> High Value | Q31: =COUNTIF($F:$F,F31) -> 29 | R31: =UPPER(LEFT(D31,1)&MID(D31,FIND(" ",D31)+1,1)) -> EM | V31: Ayush | W31: Payal | X31: =IF(COUNTIF($V$30:$V$38,W31),W31,"-") -> -
A32: TRX0029 | B32: 45427 | C32: CUST31 | D32: Charles Allen | E32: P006 | F32: Office Chair | G32: Furniture | H32: 5 | I32: 199.99 | J32: Cash | K32: South | L32: Standard | M32: 44412 | N32: 999.95 | O32: =SUMIFS($N:$N,$D:$D,D32) -> 5089.73 | P32: =IF(O32>10000,"High Value","Normal") -> Normal | Q32: =COUNTIF($F:$F,F32) -> 15 | R32: =UPPER(LEFT(D32,1)&MID(D32,FIND(" ",D32)+1,1)) -> CA | V32: Kishan | W32: Rahul | X32: =IF(COUNTIF($V$30:$V$38,W32),W32,"-") -> -
A33: TRX0194 | B33: 45428 | C33: CUST32 | D33: Lisa Anderson | E33: P008 | F33: Bookshelf | G33: Furniture | H33: 2 | I33: 149.99 | J33: Credit Card | K33: West | L33: Basic | M33: 44823 | N33: 299.98 | O33: =SUMIFS($N:$N,$D:$D,D33) -> 2039.8 | P33: =IF(O33>10000,"High Value","Normal") -> Normal | Q33: =COUNTIF($F:$F,F33) -> 35 | R33: =UPPER(LEFT(D33,1)&MID(D33,FIND(" ",D33)+1,1)) -> LA | V33: Ajay | W33: Tanvi | X33: =IF(COUNTIF($V$30:$V$38,W33),W33,"-") -> Tanvi
A34: TRX0130 | B34: 45430 | C34: CUST33 | D34: Emma Wilson | E34: P008 | F34: Bookshelf | G34: Furniture | H34: 3 | I34: 149.99 | J34: Credit Card | K34: West | L34: Premium | M34: 45068 | N34: 449.97 | O34: =SUMIFS($N:$N,$D:$D,D34) -> 1229.88 | P34: =IF(O34>10000,"High Value","Normal") -> Normal | Q34: =COUNTIF($F:$F,F34) -> 35 | R34: =UPPER(LEFT(D34,1)&MID(D34,FIND(" ",D34)+1,1)) -> EW | V34: Unnati | W34: Kishan | X34: =IF(COUNTIF($V$30:$V$38,W34),W34,"-") -> Kishan
A35: TRX0041 | B35: 45432 | C35: CUST34 | D35: Kevin Scott | E35: P001 | F35: Laptop | G35: Electronics | H35: 1 | I35: 899.99 | J35: Credit Card | K35: West | L35: Premium | M35: 44578 | N35: 899.99 | O35: =SUMIFS($N:$N,$D:$D,D35) -> 3259.87 | P35: =IF(O35>10000,"High Value","Normal") -> Normal | Q35: =COUNTIF($F:$F,F35) -> 24 | R35: =UPPER(LEFT(D35,1)&MID(D35,FIND(" ",D35)+1,1)) -> KS | V35: Tanvi | W35: Jolly | X35: =IF(COUNTIF($V$30:$V$38,W35),W35,"-") -> -
A36: TRX0232 | B36: 45434 | C36: CUST35 | D36: Patricia Moore | E36: P007 | F36: Desk | G36: Furniture | H36: 3 | I36: 299.99 | J36: Credit Card | K36: East | L36: Basic | M36: 44824 | N36: 899.97 | O36: =SUMIFS($N:$N,$D:$D,D36) -> 9799.73 | P36: =IF(O36>10000,"High Value","Normal") -> Normal | Q36: =COUNTIF($F:$F,F36) -> 26 | R36: =UPPER(LEFT(D36,1)&MID(D36,FIND(" ",D36)+1,1)) -> PM | V36: Janvi | W36: Timple | X36: =IF(COUNTIF($V$30:$V$38,W36),W36,"-") -> -
A37: TRX0021 | B37: 45435 | C37: CUST36 | D37: Lisa Anderson | E37: P004 | F37: Coffee Maker | G37: Appliances | H37: 3 | I37: 79.99 | J37: Cash | K37: South | L37: Basic | M37: 45046 | N37: 239.97 | O37: =SUMIFS($N:$N,$D:$D,D37) -> 2039.8 | P37: =IF(O37>10000,"High Value","Normal") -> Normal | Q37: =COUNTIF($F:$F,F37) -> 14 | R37: =UPPER(LEFT(D37,1)&MID(D37,FIND(" ",D37)+1,1)) -> LA | V37: Vishwa | W37: Ayush | X37: =IF(COUNTIF($V$30:$V$38,W37),W37,"-") -> Ayush
A38: TRX0245 | B38: 45438 | C38: CUST37 | D38: Steven Turner | E38: P006 | F38: Office Chair | G38: Furniture | H38: 3 | I38: 199.99 | J38: Credit Card | K38: North | L38: Premium | M38: 45292 | N38: 599.97 | O38: =SUMIFS($N:$N,$D:$D,D38) -> 2649.83 | P38: =IF(O38>10000,"High Value","Normal") -> Normal | Q38: =COUNTIF($F:$F,F38) -> 15 | R38: =UPPER(LEFT(D38,1)&MID(D38,FIND(" ",D38)+1,1)) -> ST | V38: Shivani | W38: Unnati | X38: =IF(COUNTIF($V$30:$V$38,W38),W38,"-") -> Unnati
A39: TRX0015 | B39: 45440 | C39: CUST38 | D39: Jennifer Taylor | E39: P002 | F39: Smartphone | G39: Electronics | H39: 5 | I39: 699.99 | J39: PayPal | K39: West | L39: Standard | M39: 44407 | N39: 3499.95 | O39: =SUMIFS($N:$N,$D:$D,D39) -> 4739.85 | P39: =IF(O39>10000,"High Value","Normal") -> Normal | Q39: =COUNTIF($F:$F,F39) -> 31 | R39: =UPPER(LEFT(D39,1)&MID(D39,FIND(" ",D39)+1,1)) -> JT
A40: TRX0202 | B40: 45441 | C40: CUST39 | D40: Harry Morgan | E40: P010 | F40: Keyboard | G40: Electronics | H40: 3 | I40: 89.99 | J40: PayPal | K40: Central | L40: Premium | M40: 45120 | N40: 269.97 | O40: =SUMIFS($N:$N,$D:$D,D40) -> 5519.89 | P40: =IF(O40>10000,"High Value","Normal") -> Normal | Q40: =COUNTIF($F:$F,F40) -> 34 | R40: =UPPER(LEFT(D40,1)&MID(D40,FIND(" ",D40)+1,1)) -> HM
...

Sheet High value customer
A2: {=_xlfn.UNIQUE('Final Project Dataset'!D2:D251)} -> Paul Baker | B2: =SUMIFS('Final Project Dataset'!N:N, 'Final Project Dataset'!D:D, A2) -> 8309.74 | C2: =IF(B2>10000,"High Value","Normal") -> Normal
A3: Joseph Jackson | B3: =SUMIFS('Final Project Dataset'!N:N, 'Final Project Dataset'!D:D, A3) -> 6949.84 | C3: =IF(B3>10000,"High Value","Normal") -> Normal
A4: Kevin Scott | B4: =SUMIFS('Final Project Dataset'!N:N, 'Final Project Dataset'!D:D, A4) -> 3259.87 | C4: =IF(B4>10000,"High Value","Normal") -> Normal
A5: Kathleen Bennett | B5: =SUMIFS('Final Project Dataset'!N:N, 'Final Project Dataset'!D:D, A5) -> 4309.81 | C5: =IF(B5>10000,"High Value","Normal") -> Normal
A6: Michael Brown | B6: =SUMIFS('Final Project Dataset'!N:N, 'Final Project Dataset'!D:D, A6) -> 6169.74 | C6: =IF(B6>10000,"High Value","Normal") -> Normal
A7: Dorothy Nelson | B7: =SUMIFS('Final Project Dataset'!N:N, 'Final Project Dataset'!D:D, A7) -> 8269.79 | C7: =IF(B7>10000,"High Value","Normal") -> Normal
A8: Charles Allen | B8: =SUMIFS('Final Project Dataset'!N:N, 'Final Project Dataset'!D:D, A8) -> 5089.73 | C8: =IF(B8>10000,"High Value","Normal") -> Normal
A9: Robert Thomas | B9: =SUMIFS('Final Project Dataset'!N:N, 'Final Project Dataset'!D:D, A9) -> 3509.9 | C9: =IF(B9>10000,"High Value","Normal") -> Normal
A10: Karen Hill | B10: =SUMIFS('Final Project Dataset'!N:N, 'Final Project Dataset'!D:D, A10) -> 8009.77 | C10: =IF(B10>10000,"High Value","Normal") -> Normal
A11: Susan Green | B11: =SUMIFS('Final Project Dataset'!N:N, 'Final Project Dataset'!D:D, A11) -> 1979.89 | C11: =IF(B11>10000,"High Value","Normal") -> Normal
A12: Peter Richardson | B12: =SUMIFS('Final Project Dataset'!N:N, 'Final Project Dataset'!D:D, A12) -> 5949.85 | C12: =IF(B12>10000,"High Value","Normal") -> Normal
A13: Dennis Gray | B13: =SUMIFS('Final Project Dataset'!N:N, 'Final Project Dataset'!D:D, A13) -> 479.92 | C13: =IF(B13>10000,"High Value","Normal") -> Normal
A14: Michelle Rogers | B14: =SUMIFS('Final Project Dataset'!N:N, 'Final Project Dataset'!D:D, A14) -> 4199.94 | C14: =IF(B14>10000,"High Value","Normal") -> Normal
... A51: John Smith | B51: =SUMIFS('Final Project Dataset'!N:N, 'Final Project Dataset'!D:D, A51) -> 599.96 | C51: =IF(B51>10000,"High Value","Normal") -> Normal

Sheet Filter
A1: Select Category | B1: Transaction_ID | C1: Date | D1: Customer_ID | E1: Customer_Name | F1: Product_ID | G1: Product_Name | H1: Category | I1: Quantity | J1: Unit_Price | K1: Payment_Method | L1: Region | M1: Customer_Segment | N1: Customer_Since | O1: Total_Amount
A2: Electronics | B2: {=_xlfn._xlws.FILTER('Final Project Dataset'!A:N,'Final Project Dataset'!G:G=Filter!A2,"-")} -> TRX0155 | C2: 45393 | D2: CUST01 | E2: Paul Baker | F2: P009 | G2: Monitor | H2: Electronics | I2: 3 | J2: 249.99 | K2: Cash | L2: Central | M2: Basic | N2: 44425 | O2: 749.97
B3: TRX0023 | C3: 45396 | D3: CUST02 | E3: Joseph Jackson | F3: P009 | G3: Monitor | H3: Electronics | I3: 3 | J3: 249.99 | K3: Credit Card | L3: Central | M3: Premium | N3: 44575 | O3: 749.97
B4: TRX0193 | C4: 45403 | D4: CUST07 | E4: Dorothy Nelson | F4: P003 | G4: Headphones | H4: Electronics | I4: 5 | J4: 149.99 | K4: Credit Card | L4: Central | M4: Standard | N4: 44418 | O4: 749.95
B5: TRX0135 | C5: 45405 | D5: CUST09 | E5: Robert Thomas | F5: P001 | G5: Laptop | H5: Electronics | I5: 3 | J5: 899.99 | K5: PayPal | L5: East | M5: Standard | N5: 45299 | O5: 2699.97
B6: TRX0191 | C6: 45409 | D6: CUST15 | E6: Michelle Rogers | F6: P002 | G6: Smartphone | H6: Electronics | I6: 3 | J6: 699.99 | K6: Credit Card | L6: West | M6: Basic | N6: 44577 | O6: 2099.97
B7: TRX0230 | C7: 45409 | D7: CUST16 | E7: George Adams | F7: P001 | G7: Laptop | H7: Electronics | I7: 1 | J7: 899.99 | K7: Debit Card | L7: North | M7: Standard | N7: 44920 | O7: 899.99
B8: TRX0134 | C8: 45410 | D8: CUST18 | E8: Maria Garcia | F8: P002 | G8: Smartphone | H8: Electronics | I8: 2 | J8: 699.99 | K8: Cash | L8: North | M8: Basic | N8: 44781 | O8: 1399.98
B9: TRX0122 | C9: 45410 | D9: CUST19 | E9: Mark Carter | F9: P001 | G9: Laptop | H9: Electronics | I9: 4 | J9: 899.99 | K9: Credit Card | L9: West | M9: Standard | N9: 45327 | O9: 3599.96
B10: TRX0222 | C10: 45410 | D10: CUST20 | E10: Virginia Sanders | F10: P009 | G10: Monitor | H10: Electronics | I10: 3 | J10: 249.99 | K10: Credit Card | L10: North | M10: Premium | N10: 45224 | O10: 749.97
B11: TRX0231 | C11: 45412 | D11: CUST21 | E11: Barbara Young | F11: P002 | G11: Smartphone | H11: Electronics | I11: 5 | J11: 699.99 | K11: Cash | L11: West | M11: Basic | N11: 45167 | O11: 3499.95
B12: TRX0239 | C12: 45413 | D12: CUST22 | E12: Patricia Moore | F12: P002 | G12: Smartphone | H12: Electronics | I12: 4 | J12: 699.99 | K12: Cash | L12: East | M12: Standard | N12: 44409 | O12: 2799.96
B13: TRX0204 | C13: 45415 | D13: CUST23 | E13: Cynthia Price | F13: P009 | G13: Monitor | H13: Electronics | I13: 4 | J13: 249.99 | K13: PayPal | L13: North | M13: Standard | N13: 44468 | O13: 999.96
B14: TRX0071 | C14: 45422 | D14: CUST25 | E14: Nancy Collins | F14: P009 | G14: Monitor | H14: Electronics | I14: 5 | J14: 249.99 | K14: Credit Card | L14: West | M14: Standard | N14: 44525 | O14: 1249.95
... B132: TRX0064 | C132: 45758 | D132: CUST250 | E132: Steven Turner | F132: P010 | G132: Keyboard | H132: Electronics | I132: 3 | J132: 89.99 | K132: Debit Card | L132: North | M132: Premium | N132: 44878 | O132: 269.97

Sheet liner regression
A1: SUMMARY OUTPUT
A3: Regression Statistics
A4: Multiple R | B4: 0.45808036
A5: R Square | B5: 0.20983762
A6: Adjusted R Square | B6: 0.20665148
A7: Standard Error | B7: 1.1906792
A8: Observations | B8: 250
A10: ANOVA
B11: df | C11: SS | D11: MS | E11: F | F11: Significance F
A12: Regression | B12: 1 | C12: 93.370185 | D12: 93.370185 | E12: 65.859537 | F12: 2.2586479e-14
A13: Residual | B13: 248 | C13: 351.59381 | D13: 1.417717
A14: Total | B14: 249 | C14: 444.964
B16: Coefficients | C16: Standard Error | D16: t Stat | E16: P-value | F16: Lower 95% | G16: Upper 95% | H16: Lower 95.0% | I16: Upper 95.0%
A17: Intercept | B17: 2.468256 | C17: 0.10079723 | D17: 24.487341 | E17: 3.9188263e-68 | F17: 2.2697283 | G17: 2.6667838 | H17: 2.2697283 | I17: 2.6667838
A18: X Variable 1 | B18: 0.00059310844 | C18: 7.3084414e-05 | D18: 8.1153889 | E18: 2.2586479e-14 | F18: 0.00044916316 | G18: 0.00073705372 | H18: 0.00044916316 | I18: 0.00073705372

Sheet Pivot table and chart
B3: Row Labels | C3: Sum of Total_Amount | E3: Row Labels | F3: Sum of Total_Amount | H3: Row Labels | I3: Sum of Total_Amount | K3: Row Labels | L3: Sum of Total_Amount
B4: Central | C4: 41288.34 | E4: Appliances | F4: 8338.74 | H4: Blender | I4: 5219.13 | K4: Jan | L4: 25799.15
B5: East | C5: 59288.39 | E5: Electronics | F5: 171756.05 | H5: Bookshelf | I5: 15298.98 | K5: Feb | L5: 16069.38
B6: North | C6: 50808.31 | E6: Furniture | F6: 49097.68 | H6: Coffee Maker | I6: 3119.61 | K6: Mar | L6: 19899.38
B7: South | C7: 36398.75 | E7: Grand Total | F7: 229192.47 | H7: Desk | I7: 23399.22 | K7: Apr | L7: 27899.16
B8: West | C8: 41408.68 | H8: Headphones | I8: 7049.53 | K8: May | L8: 17039.35
B9: Grand Total | C9: 229192.47 | H9: Keyboard | I9: 8009.11 | K9: Jun | L9: 19299.45
H10: Laptop | I10: 67499.25 | K10: Jul | L10: 18479.4
H11: Monitor | I11: 21999.12 | K11: Aug | L11: 15759.43
H12: Office Chair | I12: 10399.48 | K12: Sep | L12: 12989.51
H13: Smartphone | I13: 67199.04 | K13: Oct | L13: 20609.52
H14: Grand Total | I14: 229192.47 | K14: Nov | L14: 12309.44
K15: Dec | L15: 23039.3
K16: Grand Total | L16: 229192.47

Sheet Dashboard
